Workbook

Sheet DATA
G1: Options: | H1: Q1 2024
H2: Q2 2024
H3: Q3 2024
H4: Q4 2024
B5: ACTIVE TABLE FOR SELECTED | E5: =DASHBOARD!D2 -> Q4 2024
C8: Q1
C9: October | D9: November | E9: December | F9: October | G9: November | H9: December | I9: October | J9: November | K9: December | L9: October | M9: November | N9: December | O9: October | P9: November | Q9: December | R9: October | S9: November | T9: December | U9: October | V9: November | W9: December | X9: October | Y9: November | Z9: December | AA9: October | AB9: November | AC9: December | AD9: October | AE9: November | AF9: December | AG9: October | AH9: November | AI9: December | AJ9: October | AK9: November | AL9: December | AM9: October | AN9: November | AO9: December | AP9: October | AQ9: November | AR9: December
C10: Revenue | D10: Revenue | E10: Revenue | F10: Target Revenue | G10: Target Revenue | H10: Target Revenue | I10: Previous Year Revenue | J10: Previous Year Revenue | K10: Previous Year Revenue | L10: Number of Customers | M10: Number of Customers | N10: Number of Customers | O10: Number of New Customers Target | P10: Number of New Customers Target | Q10: Number of New Customers Target | R10: Number of New Customers | S10: Number of New Customers | T10: Number of New Customers | U10: Number of New Customers Previous Year | V10: Number of New Customers Previous Year | W10: Number of New Customers Previous Year | X10: Customer Acquisition Costs | Y10: Customer Acquisition Costs | Z10: Customer Acquisition Costs | AA10: Customer AC (per customer) | AB10: Customer AC (per customer) | AC10: Customer AC (per customer) | AD10: Customer AC (per customer) Target | AE10: Customer AC (per customer) Target | AF10: Customer AC (per customer) Target | AG10: Customer Aquis. Costs (per customer) PY | AH10: Customer Aquis. Costs (per customer) PY | AI10: Customer Aquis. Costs (per customer) PY | AJ10: Revenue per Customer | AK10: Revenue per Customer | AL10: Revenue per Customer | AM10: Revenue per Customer PY | AN10: Revenue per Customer PY | AO10: Revenue per Customer PY | AP10: Target Revenue per Customer | AQ10: Target Revenue per Customer | AR10: Target Revenue per Customer
B11: Jacob | C11: {=_xlfn.SWITCH($E$5,"Q4 2024",_xlfn.XLOOKUP($B11,$B$63:$B$68,C$63:C$68), "Q3 2024",_xlfn.XLOOKUP($B11,$B$52:$B$57,C$52:C$57), "Q2 2024",_xlfn.XLOOKUP($B11,$B$41:$B$46,C$41:C$46), "Q1 2024",_xlfn.XLOOKUP($B11,$B$30:$B$35,C$30:C$35))} -> 145000 | D11: {=_xlfn.SWITCH($E$5,"Q4 2024",_xlfn.XLOOKUP($B11,$B$63:$B$68,D$63:D$68), "Q3 2024",_xlfn.XLOOKUP($B11,$B$52:$B$57,D$52:D$57), "Q2 2024",_xlfn.XLOOKUP($B11,$B$41:$B$46,D$41:D$46), "Q1 2024",_xlfn.XLOOKUP($B11,$B$30:$B$35,D$30:D$35))} -> 150000 | E11: {=_xlfn.SWITCH($E$5,"Q4 2024",_xlfn.XLOOKUP($B11,$B$63:$B$68,E$63:E$68), "Q3 2024",_xlfn.XLOOKUP($B11,$B$52:$B$57,E$52:E$57), "Q2 2024",_xlfn.XLOOKUP($B11,$B$41:$B$46,E$41:E$46), "Q1 2024",_xlfn.XLOOKUP($B11,$B$30:$B$35,E$30:E$35))} -> 150000 | F11: {=_xlfn.SWITCH($E$5,"Q4 2024",_xlfn.XLOOKUP($B11,$B$63:$B$68,F$63:F$68), "Q3 2024",_xlfn.XLOOKUP($B11,$B$52:$B$57,F$52:F$57), "Q2 2024",_xlfn.XLOOKUP($B11,$B$41:$B$46,F$41:F$46), "Q1 2024",_xlfn.XLOOKUP($B11,$B$30:$B$35,F$30:F$35))} -> 165000 | G11: {=_xlfn.SWITCH($E$5,"Q4 2024",_xlfn.XLOOKUP($B11,$B$63:$B$68,G$63:G$68), "Q3 2024",_xlfn.XLOOKUP($B11,$B$52:$B$57,G$52:G$57), "Q2 2024",_xlfn.XLOOKUP($B11,$B$41:$B$46,G$41:G$46), "Q1 2024",_xlfn.XLOOKUP($B11,$B$30:$B$35,G$30:G$35))} -> 155000 | H11: {=_xlfn.SWITCH($E$5,"Q4 2024",_xlfn.XLOOKUP($B11,$B$63:$B$68,H$63:H$68), "Q3 2024",_xlfn.XLOOKUP($B11,$B$52:$B$57,H$52:H$57), "Q2 2024",_xlfn.XLOOKUP($B11,$B$41:$B$46,H$41:H$46), "Q1 2024",_xlfn.XLOOKUP($B11,$B$30:$B$35,H$30:H$35))} -> 145000 | I11: {=_xlfn.SWITCH($E$5,"Q4 2024",_xlfn.XLOOKUP($B11,$B$63:$B$68,I$63:I$68), "Q3 2024",_xlfn.XLOOKUP($B11,$B$52:$B$57,I$52:I$57), "Q2 2024",_xlfn.XLOOKUP($B11,$B$41:$B$46,I$41:I$46), "Q1 2024",_xlfn.XLOOKUP($B11,$B$30:$B$35,I$30:I$35))} -> 155000 | J11: {=_xlfn.SWITCH($E$5,"Q4 2024",_xlfn.XLOOKUP($B11,$B$63:$B$68,J$63:J$68), "Q3 2024",_xlfn.XLOOKUP($B11,$B$52:$B$57,J$52:J$57), "Q2 2024",_xlfn.XLOOKUP($B11,$B$41:$B$46,J$41:J$46), "Q1 2024",_xlfn.XLOOKUP($B11,$B$30:$B$35,J$30:J$35))} -> 125000 | ... AR11: {=_xlfn.SWITCH($E$5,"Q4 2024",_xlfn.XLOOKUP($B11,$B$63:$B$68,AR$63:AR$68), "Q3 2024",_xlfn.XLOOKUP($B11,$B$52:$B$57,AR$52:AR$57), "Q2 2024",_xlfn.XLOOKUP($B11,$B$41:$B$46,AR$41:AR$46), "Q1 2024",_xlfn.XLOOKUP($B11,$B$30:$B$35,AR$30:AR$35))} -> 2350
B12: Arnold | C12: {=_xlfn.SWITCH($E$5,"Q4 2024",_xlfn.XLOOKUP($B12,$B$63:$B$68,C$63:C$68), "Q3 2024",_xlfn.XLOOKUP($B12,$B$52:$B$57,C$52:C$57), "Q2 2024",_xlfn.XLOOKUP($B12,$B$41:$B$46,C$41:C$46), "Q1 2024",_xlfn.XLOOKUP($B12,$B$30:$B$35,C$30:C$35))} -> 115000 | D12: {=_xlfn.SWITCH($E$5,"Q4 2024",_xlfn.XLOOKUP($B12,$B$63:$B$68,D$63:D$68), "Q3 2024",_xlfn.XLOOKUP($B12,$B$52:$B$57,D$52:D$57), "Q2 2024",_xlfn.XLOOKUP($B12,$B$41:$B$46,D$41:D$46), "Q1 2024",_xlfn.XLOOKUP($B12,$B$30:$B$35,D$30:D$35))} -> 140000 | E12: {=_xlfn.SWITCH($E$5,"Q4 2024",_xlfn.XLOOKUP($B12,$B$63:$B$68,E$63:E$68), "Q3 2024",_xlfn.XLOOKUP($B12,$B$52:$B$57,E$52:E$57), "Q2 2024",_xlfn.XLOOKUP($B12,$B$41:$B$46,E$41:E$46), "Q1 2024",_xlfn.XLOOKUP($B12,$B$30:$B$35,E$30:E$35))} -> 170000 | F12: {=_xlfn.SWITCH($E$5,"Q4 2024",_xlfn.XLOOKUP($B12,$B$63:$B$68,F$63:F$68), "Q3 2024",_xlfn.XLOOKUP($B12,$B$52:$B$57,F$52:F$57), "Q2 2024",_xlfn.XLOOKUP($B12,$B$41:$B$46,F$41:F$46), "Q1 2024",_xlfn.XLOOKUP($B12,$B$30:$B$35,F$30:F$35))} -> 165000 | G12: {=_xlfn.SWITCH($E$5,"Q4 2024",_xlfn.XLOOKUP($B12,$B$63:$B$68,G$63:G$68), "Q3 2024",_xlfn.XLOOKUP($B12,$B$52:$B$57,G$52:G$57), "Q2 2024",_xlfn.XLOOKUP($B12,$B$41:$B$46,G$41:G$46), "Q1 2024",_xlfn.XLOOKUP($B12,$B$30:$B$35,G$30:G$35))} -> 155000 | H12: {=_xlfn.SWITCH($E$5,"Q4 2024",_xlfn.XLOOKUP($B12,$B$63:$B$68,H$63:H$68), "Q3 2024",_xlfn.XLOOKUP($B12,$B$52:$B$57,H$52:H$57), "Q2 2024",_xlfn.XLOOKUP($B12,$B$41:$B$46,H$41:H$46), "Q1 2024",_xlfn.XLOOKUP($B12,$B$30:$B$35,H$30:H$35))} -> 145000 | I12: {=_xlfn.SWITCH($E$5,"Q4 2024",_xlfn.XLOOKUP($B12,$B$63:$B$68,I$63:I$68), "Q3 2024",_xlfn.XLOOKUP($B12,$B$52:$B$57,I$52:I$57), "Q2 2024",_xlfn.XLOOKUP($B12,$B$41:$B$46,I$41:I$46), "Q1 2024",_xlfn.XLOOKUP($B12,$B$30:$B$35,I$30:I$35))} -> 140000 | J12: {=_xlfn.SWITCH($E$5,"Q4 2024",_xlfn.XLOOKUP($B12,$B$63:$B$68,J$63:J$68), "Q3 2024",_xlfn.XLOOKUP($B12,$B$52:$B$57,J$52:J$57), "Q2 2024",_xlfn.XLOOKUP($B12,$B$41:$B$46,J$41:J$46), "Q1 2024",_xlfn.XLOOKUP($B12,$B$30:$B$35,J$30:J$35))} -> 125000 | ... AR12: {=_xlfn.SWITCH($E$5,"Q4 2024",_xlfn.XLOOKUP($B12,$B$63:$B$68,AR$63:AR$68), "Q3 2024",_xlfn.XLOOKUP($B12,$B$52:$B$57,AR$52:AR$57), "Q2 2024",_xlfn.XLOOKUP($B12,$B$41:$B$46,AR$41:AR$46), "Q1 2024",_xlfn.XLOOKUP($B12,$B$30:$B$35,AR$30:AR$35))} -> 2350
B13: Naomi | C13: {=_xlfn.SWITCH($E$5,"Q4 2024",_xlfn.XLOOKUP($B13,$B$63:$B$68,C$63:C$68), "Q3 2024",_xlfn.XLOOKUP($B13,$B$52:$B$57,C$52:C$57), "Q2 2024",_xlfn.XLOOKUP($B13,$B$41:$B$46,C$41:C$46), "Q1 2024",_xlfn.XLOOKUP($B13,$B$30:$B$35,C$30:C$35))} -> 165000 | D13: {=_xlfn.SWITCH($E$5,"Q4 2024",_xlfn.XLOOKUP($B13,$B$63:$B$68,D$63:D$68), "Q3 2024",_xlfn.XLOOKUP($B13,$B$52:$B$57,D$52:D$57), "Q2 2024",_xlfn.XLOOKUP($B13,$B$41:$B$46,D$41:D$46), "Q1 2024",_xlfn.XLOOKUP($B13,$B$30:$B$35,D$30:D$35))} -> 140000 | E13: {=_xlfn.SWITCH($E$5,"Q4 2024",_xlfn.XLOOKUP($B13,$B$63:$B$68,E$63:E$68), "Q3 2024",_xlfn.XLOOKUP($B13,$B$52:$B$57,E$52:E$57), "Q2 2024",_xlfn.XLOOKUP($B13,$B$41:$B$46,E$41:E$46), "Q1 2024",_xlfn.XLOOKUP($B13,$B$30:$B$35,E$30:E$35))} -> 145000 | F13: {=_xlfn.SWITCH($E$5,"Q4 2024",_xlfn.XLOOKUP($B13,$B$63:$B$68,F$63:F$68), "Q3 2024",_xlfn.XLOOKUP($B13,$B$52:$B$57,F$52:F$57), "Q2 2024",_xlfn.XLOOKUP($B13,$B$41:$B$46,F$41:F$46), "Q1 2024",_xlfn.XLOOKUP($B13,$B$30:$B$35,F$30:F$35))} -> 165000 | G13: {=_xlfn.SWITCH($E$5,"Q4 2024",_xlfn.XLOOKUP($B13,$B$63:$B$68,G$63:G$68), "Q3 2024",_xlfn.XLOOKUP($B13,$B$52:$B$57,G$52:G$57), "Q2 2024",_xlfn.XLOOKUP($B13,$B$41:$B$46,G$41:G$46), "Q1 2024",_xlfn.XLOOKUP($B13,$B$30:$B$35,G$30:G$35))} -> 155000 | H13: {=_xlfn.SWITCH($E$5,"Q4 2024",_xlfn.XLOOKUP($B13,$B$63:$B$68,H$63:H$68), "Q3 2024",_xlfn.XLOOKUP($B13,$B$52:$B$57,H$52:H$57), "Q2 2024",_xlfn.XLOOKUP($B13,$B$41:$B$46,H$41:H$46), "Q1 2024",_xlfn.XLOOKUP($B13,$B$30:$B$35,H$30:H$35))} -> 145000 | I13: {=_xlfn.SWITCH($E$5,"Q4 2024",_xlfn.XLOOKUP($B13,$B$63:$B$68,I$63:I$68), "Q3 2024",_xlfn.XLOOKUP($B13,$B$52:$B$57,I$52:I$57), "Q2 2024",_xlfn.XLOOKUP($B13,$B$41:$B$46,I$41:I$46), "Q1 2024",_xlfn.XLOOKUP($B13,$B$30:$B$35,I$30:I$35))} -> 165000 | J13: {=_xlfn.SWITCH($E$5,"Q4 2024",_xlfn.XLOOKUP($B13,$B$63:$B$68,J$63:J$68), "Q3 2024",_xlfn.XLOOKUP($B13,$B$52:$B$57,J$52:J$57), "Q2 2024",_xlfn.XLOOKUP($B13,$B$41:$B$46,J$41:J$46), "Q1 2024",_xlfn.XLOOKUP($B13,$B$30:$B$35,J$30:J$35))} -> 150000 | ... AR13: {=_xlfn.SWITCH($E$5,"Q4 2024",_xlfn.XLOOKUP($B13,$B$63:$B$68,AR$63:AR$68), "Q3 2024",_xlfn.XLOOKUP($B13,$B$52:$B$57,AR$52:AR$57), "Q2 2024",_xlfn.XLOOKUP($B13,$B$41:$B$46,AR$41:AR$46), "Q1 2024",_xlfn.XLOOKUP($B13,$B$30:$B$35,AR$30:AR$35))} -> 2350
B14: David | C14: {=_xlfn.SWITCH($E$5,"Q4 2024",_xlfn.XLOOKUP($B14,$B$63:$B$68,C$63:C$68), "Q3 2024",_xlfn.XLOOKUP($B14,$B$52:$B$57,C$52:C$57), "Q2 2024",_xlfn.XLOOKUP($B14,$B$41:$B$46,C$41:C$46), "Q1 2024",_xlfn.XLOOKUP($B14,$B$30:$B$35,C$30:C$35))} -> 125000 | D14: {=_xlfn.SWITCH($E$5,"Q4 2024",_xlfn.XLOOKUP($B14,$B$63:$B$68,D$63:D$68), "Q3 2024",_xlfn.XLOOKUP($B14,$B$52:$B$57,D$52:D$57), "Q2 2024",_xlfn.XLOOKUP($B14,$B$41:$B$46,D$41:D$46), "Q1 2024",_xlfn.XLOOKUP($B14,$B$30:$B$35,D$30:D$35))} -> 155000 | E14: {=_xlfn.SWITCH($E$5,"Q4 2024",_xlfn.XLOOKUP($B14,$B$63:$B$68,E$63:E$68), "Q3 2024",_xlfn.XLOOKUP($B14,$B$52:$B$57,E$52:E$57), "Q2 2024",_xlfn.XLOOKUP($B14,$B$41:$B$46,E$41:E$46), "Q1 2024",_xlfn.XLOOKUP($B14,$B$30:$B$35,E$30:E$35))} -> 155000 | F14: {=_xlfn.SWITCH($E$5,"Q4 2024",_xlfn.XLOOKUP($B14,$B$63:$B$68,F$63:F$68), "Q3 2024",_xlfn.XLOOKUP($B14,$B$52:$B$57,F$52:F$57), "Q2 2024",_xlfn.XLOOKUP($B14,$B$41:$B$46,F$41:F$46), "Q1 2024",_xlfn.XLOOKUP($B14,$B$30:$B$35,F$30:F$35))} -> 165000 | G14: {=_xlfn.SWITCH($E$5,"Q4 2024",_xlfn.XLOOKUP($B14,$B$63:$B$68,G$63:G$68), "Q3 2024",_xlfn.XLOOKUP($B14,$B$52:$B$57,G$52:G$57), "Q2 2024",_xlfn.XLOOKUP($B14,$B$41:$B$46,G$41:G$46), "Q1 2024",_xlfn.XLOOKUP($B14,$B$30:$B$35,G$30:G$35))} -> 155000 | H14: {=_xlfn.SWITCH($E$5,"Q4 2024",_xlfn.XLOOKUP($B14,$B$63:$B$68,H$63:H$68), "Q3 2024",_xlfn.XLOOKUP($B14,$B$52:$B$57,H$52:H$57), "Q2 2024",_xlfn.XLOOKUP($B14,$B$41:$B$46,H$41:H$46), "Q1 2024",_xlfn.XLOOKUP($B14,$B$30:$B$35,H$30:H$35))} -> 145000 | I14: {=_xlfn.SWITCH($E$5,"Q4 2024",_xlfn.XLOOKUP($B14,$B$63:$B$68,I$63:I$68), "Q3 2024",_xlfn.XLOOKUP($B14,$B$52:$B$57,I$52:I$57), "Q2 2024",_xlfn.XLOOKUP($B14,$B$41:$B$46,I$41:I$46), "Q1 2024",_xlfn.XLOOKUP($B14,$B$30:$B$35,I$30:I$35))} -> 150000 | J14: {=_xlfn.SWITCH($E$5,"Q4 2024",_xlfn.XLOOKUP($B14,$B$63:$B$68,J$63:J$68), "Q3 2024",_xlfn.XLOOKUP($B14,$B$52:$B$57,J$52:J$57), "Q2 2024",_xlfn.XLOOKUP($B14,$B$41:$B$46,J$41:J$46), "Q1 2024",_xlfn.XLOOKUP($B14,$B$30:$B$35,J$30:J$35))} -> 145000 | ... AR14: {=_xlfn.SWITCH($E$5,"Q4 2024",_xlfn.XLOOKUP($B14,$B$63:$B$68,AR$63:AR$68), "Q3 2024",_xlfn.XLOOKUP($B14,$B$52:$B$57,AR$52:AR$57), "Q2 2024",_xlfn.XLOOKUP($B14,$B$41:$B$46,AR$41:AR$46), "Q1 2024",_xlfn.XLOOKUP($B14,$B$30:$B$35,AR$30:AR$35))} -> 2350
B15: Ariel | C15: {=_xlfn.SWITCH($E$5,"Q4 2024",_xlfn.XLOOKUP($B15,$B$63:$B$68,C$63:C$68), "Q3 2024",_xlfn.XLOOKUP($B15,$B$52:$B$57,C$52:C$57), "Q2 2024",_xlfn.XLOOKUP($B15,$B$41:$B$46,C$41:C$46), "Q1 2024",_xlfn.XLOOKUP($B15,$B$30:$B$35,C$30:C$35))} -> 150000 | D15: {=_xlfn.SWITCH($E$5,"Q4 2024",_xlfn.XLOOKUP($B15,$B$63:$B$68,D$63:D$68), "Q3 2024",_xlfn.XLOOKUP($B15,$B$52:$B$57,D$52:D$57), "Q2 2024",_xlfn.XLOOKUP($B15,$B$41:$B$46,D$41:D$46), "Q1 2024",_xlfn.XLOOKUP($B15,$B$30:$B$35,D$30:D$35))} -> 130000 | E15: {=_xlfn.SWITCH($E$5,"Q4 2024",_xlfn.XLOOKUP($B15,$B$63:$B$68,E$63:E$68), "Q3 2024",_xlfn.XLOOKUP($B15,$B$52:$B$57,E$52:E$57), "Q2 2024",_xlfn.XLOOKUP($B15,$B$41:$B$46,E$41:E$46), "Q1 2024",_xlfn.XLOOKUP($B15,$B$30:$B$35,E$30:E$35))} -> 150000 | F15: {=_xlfn.SWITCH($E$5,"Q4 2024",_xlfn.XLOOKUP($B15,$B$63:$B$68,F$63:F$68), "Q3 2024",_xlfn.XLOOKUP($B15,$B$52:$B$57,F$52:F$57), "Q2 2024",_xlfn.XLOOKUP($B15,$B$41:$B$46,F$41:F$46), "Q1 2024",_xlfn.XLOOKUP($B15,$B$30:$B$35,F$30:F$35))} -> 165000 | G15: {=_xlfn.SWITCH($E$5,"Q4 2024",_xlfn.XLOOKUP($B15,$B$63:$B$68,G$63:G$68), "Q3 2024",_xlfn.XLOOKUP($B15,$B$52:$B$57,G$52:G$57), "Q2 2024",_xlfn.XLOOKUP($B15,$B$41:$B$46,G$41:G$46), "Q1 2024",_xlfn.XLOOKUP($B15,$B$30:$B$35,G$30:G$35))} -> 155000 | H15: {=_xlfn.SWITCH($E$5,"Q4 2024",_xlfn.XLOOKUP($B15,$B$63:$B$68,H$63:H$68), "Q3 2024",_xlfn.XLOOKUP($B15,$B$52:$B$57,H$52:H$57), "Q2 2024",_xlfn.XLOOKUP($B15,$B$41:$B$46,H$41:H$46), "Q1 2024",_xlfn.XLOOKUP($B15,$B$30:$B$35,H$30:H$35))} -> 145000 | I15: {=_xlfn.SWITCH($E$5,"Q4 2024",_xlfn.XLOOKUP($B15,$B$63:$B$68,I$63:I$68), "Q3 2024",_xlfn.XLOOKUP($B15,$B$52:$B$57,I$52:I$57), "Q2 2024",_xlfn.XLOOKUP($B15,$B$41:$B$46,I$41:I$46), "Q1 2024",_xlfn.XLOOKUP($B15,$B$30:$B$35,I$30:I$35))} -> 170000 | J15: {=_xlfn.SWITCH($E$5,"Q4 2024",_xlfn.XLOOKUP($B15,$B$63:$B$68,J$63:J$68), "Q3 2024",_xlfn.XLOOKUP($B15,$B$52:$B$57,J$52:J$57), "Q2 2024",_xlfn.XLOOKUP($B15,$B$41:$B$46,J$41:J$46), "Q1 2024",_xlfn.XLOOKUP($B15,$B$30:$B$35,J$30:J$35))} -> 155000 | ... AR15: {=_xlfn.SWITCH($E$5,"Q4 2024",_xlfn.XLOOKUP($B15,$B$63:$B$68,AR$63:AR$68), "Q3 2024",_xlfn.XLOOKUP($B15,$B$52:$B$57,AR$52:AR$57), "Q2 2024",_xlfn.XLOOKUP($B15,$B$41:$B$46,AR$41:AR$46), "Q1 2024",_xlfn.XLOOKUP($B15,$B$30:$B$35,AR$30:AR$35))} -> 2350
B16: TOTAL | C16: {=_xlfn.SWITCH($E$5,"Q4 2024",_xlfn.XLOOKUP($B16,$B$63:$B$68,C$63:C$68), "Q3 2024",_xlfn.XLOOKUP($B16,$B$52:$B$57,C$52:C$57), "Q2 2024",_xlfn.XLOOKUP($B16,$B$41:$B$46,C$41:C$46), "Q1 2024",_xlfn.XLOOKUP($B16,$B$30:$B$35,C$30:C$35))} -> 700000 | D16: {=_xlfn.SWITCH($E$5,"Q4 2024",_xlfn.XLOOKUP($B16,$B$63:$B$68,D$63:D$68), "Q3 2024",_xlfn.XLOOKUP($B16,$B$52:$B$57,D$52:D$57), "Q2 2024",_xlfn.XLOOKUP($B16,$B$41:$B$46,D$41:D$46), "Q1 2024",_xlfn.XLOOKUP($B16,$B$30:$B$35,D$30:D$35))} -> 715000 | E16: {=_xlfn.SWITCH($E$5,"Q4 2024",_xlfn.XLOOKUP($B16,$B$63:$B$68,E$63:E$68), "Q3 2024",_xlfn.XLOOKUP($B16,$B$52:$B$57,E$52:E$57), "Q2 2024",_xlfn.XLOOKUP($B16,$B$41:$B$46,E$41:E$46), "Q1 2024",_xlfn.XLOOKUP($B16,$B$30:$B$35,E$30:E$35))} -> 770000 | F16: {=_xlfn.SWITCH($E$5,"Q4 2024",_xlfn.XLOOKUP($B16,$B$63:$B$68,F$63:F$68), "Q3 2024",_xlfn.XLOOKUP($B16,$B$52:$B$57,F$52:F$57), "Q2 2024",_xlfn.XLOOKUP($B16,$B$41:$B$46,F$41:F$46), "Q1 2024",_xlfn.XLOOKUP($B16,$B$30:$B$35,F$30:F$35))} -> 825000 | G16: {=_xlfn.SWITCH($E$5,"Q4 2024",_xlfn.XLOOKUP($B16,$B$63:$B$68,G$63:G$68), "Q3 2024",_xlfn.XLOOKUP($B16,$B$52:$B$57,G$52:G$57), "Q2 2024",_xlfn.XLOOKUP($B16,$B$41:$B$46,G$41:G$46), "Q1 2024",_xlfn.XLOOKUP($B16,$B$30:$B$35,G$30:G$35))} -> 775000 | H16: {=_xlfn.SWITCH($E$5,"Q4 2024",_xlfn.XLOOKUP($B16,$B$63:$B$68,H$63:H$68), "Q3 2024",_xlfn.XLOOKUP($B16,$B$52:$B$57,H$52:H$57), "Q2 2024",_xlfn.XLOOKUP($B16,$B$41:$B$46,H$41:H$46), "Q1 2024",_xlfn.XLOOKUP($B16,$B$30:$B$35,H$30:H$35))} -> 725000 | I16: {=_xlfn.SWITCH($E$5,"Q4 2024",_xlfn.XLOOKUP($B16,$B$63:$B$68,I$63:I$68), "Q3 2024",_xlfn.XLOOKUP($B16,$B$52:$B$57,I$52:I$57), "Q2 2024",_xlfn.XLOOKUP($B16,$B$41:$B$46,I$41:I$46), "Q1 2024",_xlfn.XLOOKUP($B16,$B$30:$B$35,I$30:I$35))} -> 780000 | J16: {=_xlfn.SWITCH($E$5,"Q4 2024",_xlfn.XLOOKUP($B16,$B$63:$B$68,J$63:J$68), "Q3 2024",_xlfn.XLOOKUP($B16,$B$52:$B$57,J$52:J$57), "Q2 2024",_xlfn.XLOOKUP($B16,$B$41:$B$46,J$41:J$46), "Q1 2024",_xlfn.XLOOKUP($B16,$B$30:$B$35,J$30:J$35))} -> 700000 | ... AR16: {=_xlfn.SWITCH($E$5,"Q4 2024",_xlfn.XLOOKUP($B16,$B$63:$B$68,AR$63:AR$68), "Q3 2024",_xlfn.XLOOKUP($B16,$B$52:$B$57,AR$52:AR$57), "Q2 2024",_xlfn.XLOOKUP($B16,$B$41:$B$46,AR$41:AR$46), "Q1 2024",_xlfn.XLOOKUP($B16,$B$30:$B$35,AR$30:AR$35))} -> 2350
B18: TOTAL REVENUE PER YEAR | D18: =SUM(C35:E35,C46:E46,C57:E57,C68:E68) -> 9271500
B19: TOTAL CUSTOMERS PER YEAR | D19: =SUM(L35:N35,L46:N46,L57:N57,L68:N68) -> 3799
B20: NEW CUSTOMERS PER YEAR | D20: =SUM(R35:T35,R46:T46,R57:T57,R68:T68) -> 1228
B21: REVENUE PER CUSTOMER | D21: =D18/D19 -> 2440.5107
C27: Q1 2023
C28: January | D28: February | E28: March | F28: January | G28: February | H28: March | I28: January | J28: February | K28: March | L28: January | M28: February | N28: March | O28: January | P28: February | Q28: March | R28: January | S28: February | T28: March | U28: January | V28: February | W28: March | X28: January | Y28: February | Z28: March | AA28: January | AB28: February | AC28: March | AD28: January | AE28: February | AF28: March | AG28: January | AH28: February | AI28: March | AJ28: January | AK28: February | AL28: March | AM28: January | AN28: February | AO28: March | AP28: January | AQ28: February | AR28: March
C29: Revenue | D29: Revenue | E29: Revenue | F29: Target Revenue | G29: Target Revenue | H29: Target Revenue | I29: Previous Year Revenue | J29: Previous Year Revenue | K29: Previous Year Revenue | L29: Number of Customers | M29: Number of Customers | N29: Number of Customers | O29: Number of New Customers Target | P29: Number of New Customers Target | Q29: Number of New Customers Target | R29: Number of New Customers | S29: Number of New Customers | T29: Number of New Customers | U29: Number of New Customers Previous Year | V29: Number of New Customers Previous Year | W29: Number of New Customers Previous Year | X29: Customer Acquisition Costs | Y29: Customer Acquisition Costs | Z29: Customer Acquisition Costs | AA29: Customer AC (per customer) | AB29: Customer AC (per customer) | AC29: Customer AC (per customer) | AD29: Customer AC (per customer) Target | AE29: Customer AC (per customer) Target | AF29: Customer AC (per customer) Target | AG29: Customer Aquis. Costs (per customer) PY | AH29: Customer Aquis. Costs (per customer) PY | AI29: Customer Aquis. Costs (per customer) PY | AJ29: Revenue per Customer | AK29: Revenue per Customer | AL29: Revenue per Customer | AM29: Revenue per Customer PY | AN29: Revenue per Customer PY | AO29: Revenue per Customer PY | AP29: Target Revenue per Customer | AQ29: Target Revenue per Customer | AR29: Target Revenue per Customer
B30: Jacob | C30: 135000 | D30: 130000 | E30: 160000 | F30: 150000 | G30: 140000 | H30: 150000 | I30: 115000 | J30: 140000 | K30: 160000 | L30: 57 | M30: 58 | N30: 63 | O30: 25 | P30: 20 | Q30: 25 | R30: 10 | S30: 11 | T30: 18 | U30: 9 | V30: 12 | W30: 14 | X30: 4200 | Y30: 5000 | Z30: 5500 | AA30: 420 | AB30: 454.55 | AC30: 305.56 | AD30: 350 | AE30: 350 | AF30: 350 | AG30: 400 | AH30: 385 | AI30: 390 | AJ30: 2192.98 | AK30: 2241.38 | AL30: 2539.68 | AM30: 2200 | AN30: 2100 | AO30: 2400 | AP30: 2500 | AQ30: 2600 | AR30: 2400
B31: Arnold | C31: 170000 | D31: 160000 | E31: 185000 | F31: 150000 | G31: 140000 | H31: 150000 | I31: 160000 | J31: 130000 | K31: 125000 | L31: 74 | M31: 70 | N31: 74 | O31: 25 | P31: 20 | Q31: 25 | R31: 22 | S31: 23 | T31: 26 | U31: 17 | V31: 24 | W31: 22 | X31: 7800 | Y31: 10000 | Z31: 9000 | AA31: 354.55 | AB31: 434.78 | AC31: 346.15 | AD31: 350 | AE31: 350 | AF31: 350 | AG31: 402 | AH31: 290 | AI31: 380 | AJ31: 2432.43 | AK31: 2285.71 | AL31: 2500 | AM31: 2100 | AN31: 2200 | AO31: 2300 | AP31: 2500 | AQ31: 2600 | AR31: 2400
B32: Naomi | C32: 175000 | D32: 135000 | E32: 145000 | F32: 150000 | G32: 140000 | H32: 150000 | I32: 170000 | J32: 145000 | K32: 130000 | L32: 70 | M32: 55 | N32: 61 | O32: 25 | P32: 20 | Q32: 25 | R32: 35 | S32: 20 | T32: 17 | U32: 36 | V32: 25 | W32: 21 | X32: 13200 | Y32: 9500 | Z32: 8300 | AA32: 377.14 | AB32: 475 | AC32: 488.24 | AD32: 350 | AE32: 350 | AF32: 350 | AG32: 350 | AH32: 385 | AI32: 352 | AJ32: 2428.57 | AK32: 2454.55 | AL32: 2377.05 | AM32: 2500 | AN32: 2500 | AO32: 2300 | AP32: 2500 | AQ32: 2600 | AR32: 2400
B33: David | C33: 156000 | D33: 175000 | E33: 155000 | F33: 150000 | G33: 140000 | H33: 150000 | I33: 165000 | J33: 155000 | K33: 140000 | L33: 66 | M33: 68 | N33: 63 | O33: 25 | P33: 20 | Q33: 25 | R33: 18 | S33: 14 | T33: 24 | U33: 14 | V33: 25 | W33: 22 | X33: 6500 | Y33: 9000 | Z33: 8500 | AA33: 361.11 | AB33: 642.86 | AC33: 354.17 | AD33: 350 | AE33: 350 | AF33: 350 | AG33: 350 | AH33: 360 | AI33: 388 | AJ33: 2272.73 | AK33: 2573.53 | AL33: 2460.32 | AM33: 2200 | AN33: 2600 | AO33: 2400 | AP33: 2500 | AQ33: 2600 | AR33: 2400
B34: Ariel | C34: 135500 | D34: 190000 | E34: 140000 | F34: 150000 | G34: 140000 | H34: 150000 | I34: 155000 | J34: 120000 | K34: 150000 | L34: 71 | M34: 62 | N34: 51 | O34: 25 | P34: 20 | Q34: 25 | R34: 33 | S34: 20 | T34: 16 | U34: 20 | V34: 25 | W34: 24 | X34: 12100 | Y34: 10800 | Z34: 10500 | AA34: 366.67 | AB34: 540 | AC34: 656.25 | AD34: 350 | AE34: 350 | AF34: 350 | AG34: 385 | AH34: 350 | AI34: 406 | AJ34: 1901.41 | AK34: 3064.52 | AL34: 2745.1 | AM34: 2100 | AN34: 2800 | AO34: 2700 | AP34: 2500 | AQ34: 2600 | AR34: 2400
B35: TOTAL | C35: =SUM(C30:C34) -> 771500 | D35: =SUM(D30:D34) -> 790000 | E35: =SUM(E30:E34) -> 785000 | F35: =SUM(F30:F34) -> 750000 | G35: =SUM(G30:G34) -> 700000 | H35: =SUM(H30:H34) -> 750000 | I35: =SUM(I30:I34) -> 765000 | J35: =SUM(J30:J34) -> 690000 | ... Z35: =SUM(Z30:Z34) -> 41800 | AA35: =AVERAGE(AA30:AA34) -> 375.894 | AB35: =AVERAGE(AB30:AB34) -> 509.438 | AC35: =AVERAGE(AC30:AC34) -> 430.074 | AD35: =AVERAGE(AD30:AD34) -> 350 | AE35: =AVERAGE(AE30:AE34) -> 350 | AF35: =AVERAGE(AF30:AF34) -> 350 | AG35: =AVERAGE(AG30:AG34) -> 377.4 | AH35: =AVERAGE(AH30:AH34) -> 354 | ... AR35: =AVERAGE(AR30:AR34) -> 2400
C38: Q2 2023
C39: April | D39: May | E39: June | F39: April | G39: May | H39: June | I39: April | J39: May | K39: June | L39: April | M39: May | N39: June | O39: April | P39: May | Q39: June | R39: April | S39: May | T39: June | U39: April | V39: May | W39: June | X39: April | Y39: May | Z39: June | AA39: April | AB39: May | AC39: June | AD39: April | AE39: May | AF39: June | AG39: April | AH39: May | AI39: June | AJ39: April | AK39: May | AL39: June | AM39: April | AN39: May | AO39: June | AP39: April | AQ39: May | AR39: June
C40: Revenue | D40: Revenue | E40: Revenue | F40: Target Revenue | G40: Target Revenue | H40: Target Revenue | I40: Previous Year Revenue | J40: Previous Year Revenue | K40: Previous Year Revenue | L40: Number of Customers | M40: Number of Customers | N40: Number of Customers | O40: Number of New Customers Target | P40: Number of New Customers Target | Q40: Number of New Customers Target | R40: Number of New Customers | S40: Number of New Customers | T40: Number of New Customers | U40: Number of New Customers Previous Year | V40: Number of New Customers Previous Year | W40: Number of New Customers Previous Year | X40: Customer Acquisition Costs | Y40: Customer Acquisition Costs | Z40: Customer Acquisition Costs | AA40: Customer AC (per customer) | AB40: Customer AC (per customer) | AC40: Customer AC (per customer) | AD40: Customer AC (per customer) Target | AE40: Customer AC (per customer) Target | AF40: Customer AC (per customer) Target | AG40: Customer Aquis. Costs (per customer) PY | AH40: Customer Aquis. Costs (per customer) PY | AI40: Customer Aquis. Costs (per customer) PY | AJ40: Revenue per Customer | AK40: Revenue per Customer | AL40: Revenue per Customer | AM40: Revenue per Customer PY | AN40: Revenue per Customer PY | AO40: Revenue per Customer PY | AP40: Target Revenue per Customer | AQ40: Target Revenue per Customer | AR40: Target Revenue per Customer
B41: Jacob | C41: 130000 | D41: 135000 | E41: 150000 | F41: 150000 | G41: 160000 | H41: 140000 | I41: 125000 | J41: 160000 | K41: 135000 | L41: 58 | M41: 63 | N41: 55 | O41: 30 | P41: 30 | Q41: 25 | R41: 12 | S41: 25 | T41: 11 | U41: 11 | V41: 21 | W41: 14 | X41: 5000 | Y41: 4500 | Z41: 5000 | AA41: 416.67 | AB41: 180 | AC41: 454.55 | AD41: 400 | AE41: 350 | AF41: 350 | AG41: 400 | AH41: 385 | AI41: 390 | AJ41: 2068.97 | AK41: 2142.86 | AL41: 2727.27 | AM41: 2100 | AN41: 2000 | AO41: 2600 | AP41: 2700 | AQ41: 2500 | AR41: 2600
B42: Arnold | C42: 175000 | D42: 155000 | E42: 190000 | F42: 150000 | G42: 160000 | H42: 140000 | I42: 145000 | J42: 125000 | K42: 125000 | L42: 70 | M42: 74 | N42: 65 | O42: 30 | P42: 30 | Q42: 25 | R42: 26 | S42: 18 | T42: 23 | U42: 17 | V42: 18 | W42: 15 | X42: 9800 | Y42: 9800 | Z42: 6500 | AA42: 376.92 | AB42: 544.44 | AC42: 282.61 | AD42: 400 | AE42: 350 | AF42: 350 | AG42: 402 | AH42: 290 | AI42: 380 | AJ42: 2500 | AK42: 2094.59 | AL42: 2923.08 | AM42: 2200 | AN42: 2000 | AO42: 2200 | AP42: 2700 | AQ42: 2500 | AR42: 2600
B43: Naomi | C43: 180000 | D43: 145000 | E43: 155000 | F43: 150000 | G43: 160000 | H43: 140000 | I43: 155000 | J43: 130000 | K43: 125000 | L43: 55 | M43: 61 | N43: 44 | O43: 30 | P43: 30 | Q43: 25 | R43: 31 | S43: 25 | T43: 20 | U43: 25 | V43: 21 | W43: 22 | X43: 9500 | Y43: 10200 | Z43: 8000 | AA43: 306.45 | AB43: 408 | AC43: 400 | AD43: 400 | AE43: 350 | AF43: 350 | AG43: 350 | AH43: 385 | AI43: 352 | AJ43: 3272.73 | AK43: 2377.05 | AL43: 3522.73 | AM43: 3000 | AN43: 2200 | AO43: 2100 | AP43: 2700 | AQ43: 2500 | AR43: 2600
B44: David | C44: 160000 | D44: 180000 | E44: 175000 | F44: 150000 | G44: 160000 | H44: 140000 | I44: 145000 | J44: 140000 | K44: 160000 | L44: 68 | M44: 63 | N44: 50 | O44: 30 | P44: 30 | Q44: 25 | R44: 28 | S44: 15 | T44: 14 | U44: 17 | V44: 18 | W44: 21 | X44: 9000 | Y44: 5600 | Z44: 7000 | AA44: 321.43 | AB44: 373.33 | AC44: 500 | AD44: 400 | AE44: 350 | AF44: 350 | AG44: 350 | AH44: 360 | AI44: 388 | AJ44: 2352.94 | AK44: 2857.14 | AL44: 3500 | AM44: 2200 | AN44: 2450 | AO44: 3300 | AP44: 2700 | AQ44: 2500 | AR44: 2600
B45: Ariel | C45: 205000 | D45: 195000 | E45: 125000 | F45: 150000 | G45: 160000 | H45: 140000 | I45: 125000 | J45: 150000 | K45: 145000 | L45: 62 | M45: 51 | N45: 35 | O45: 30 | P45: 30 | Q45: 25 | R45: 25 | S45: 18 | T45: 20 | U45: 20 | V45: 13 | W45: 20 | X45: 10800 | Y45: 9500 | Z45: 9000 | AA45: 432 | AB45: 527.78 | AC45: 450 | AD45: 400 | AE45: 350 | AF45: 350 | AG45: 385 | AH45: 350 | AI45: 406 | AJ45: 3306.45 | AK45: 3823.53 | AL45: 3571.43 | AM45: 2900 | AN45: 3100 | AO45: 3100 | AP45: 2700 | AQ45: 2500 | AR45: 2600
B46: TOTAL | C46: =SUM(C41:C45) -> 850000 | D46: =SUM(D41:D45) -> 810000 | E46: =SUM(E41:E45) -> 795000 | F46: =SUM(F41:F45) -> 750000 | G46: =SUM(G41:G45) -> 800000 | H46: =SUM(H41:H45) -> 700000 | I46: =SUM(I41:I45) -> 695000 | J46: =SUM(J41:J45) -> 705000 | ... Z46: =SUM(Z41:Z45) -> 35500 | AA46: =AVERAGE(AA41:AA45) -> 370.694 | AB46: =AVERAGE(AB41:AB45) -> 406.71 | AC46: =AVERAGE(AC41:AC45) -> 417.432 | AD46: =AVERAGE(AD41:AD45) -> 400 | AE46: =AVERAGE(AE41:AE45) -> 350 | AF46: =AVERAGE(AF41:AF45) -> 350 | AG46: =AVERAGE(AG41:AG45) -> 377.4 | AH46: =AVERAGE(AH41:AH45) -> 354 | ... AR46: =AVERAGE(AR41:AR45) -> 2600
C49: Q3 2023
C50: July | D50: August | E50: September | F50: July | G50: August | H50: September | I50: July | J50: August | K50: September | L50: July | M50: August | N50: September | O50: July | P50: August | Q50: September | R50: July | S50: August | T50: September | U50: July | V50: August | W50: September | X50: July | Y50: August | Z50: September | AA50: July | AB50: August | AC50: September | AD50: July | AE50: August | AF50: September | AG50: July | AH50: August | AI50: September | AJ50: July | AK50: August | AL50: September | AM50: July | AN50: August | AO50: September | AP50: July | AQ50: August | AR50: September
C51: Revenue | D51: Revenue | E51: Revenue | F51: Target Revenue | G51: Target Revenue | H51: Target Revenue | I51: Previous Year Revenue | J51: Previous Year Revenue | K51: Previous Year Revenue | L51: Number of Customers | M51: Number of Customers | N51: Number of Customers | O51: Number of New Customers Target | P51: Number of New Customers Target | Q51: Number of New Customers Target | R51: Number of New Customers | S51: Number of New Customers | T51: Number of New Customers | U51: Number of New Customers Previous Year | V51: Number of New Customers Previous Year | W51: Number of New Customers Previous Year | X51: Customer Acquisition Costs | Y51: Customer Acquisition Costs | Z51: Customer Acquisition Costs | AA51: Customer AC (per customer) | AB51: Customer AC (per customer) | AC51: Customer AC (per customer) | AD51: Customer AC (per customer) Target | AE51: Customer AC (per customer) Target | AF51: Customer AC (per customer) Target | AG51: Customer Aquis. Costs (per customer) PY | AH51: Customer Aquis. Costs (per customer) PY | AI51: Customer Aquis. Costs (per customer) PY | AJ51: Revenue per Customer | AK51: Revenue per Customer | AL51: Revenue per Customer | AM51: Revenue per Customer PY | AN51: Revenue per Customer PY | AO51: Revenue per Customer PY | AP51: Target Revenue per Customer | AQ51: Target Revenue per Customer | AR51: Target Revenue per Customer
B52: Jacob | C52: 150000 | D52: 145000 | E52: 145000 | F52: 160000 | G52: 145000 | H52: 160000 | I52: 160000 | J52: 125000 | K52: 145000 | L52: 55 | M52: 55 | N52: 60 | O52: 20 | P52: 25 | Q52: 35 | R52: 14 | S52: 18 | T52: 17 | U52: 21 | V52: 15 | W52: 11 | X52: 8000 | Y52: 6000 | Z52: 4000 | AA52: 571.43 | AB52: 333.33 | AC52: 235.29 | AD52: 350 | AE52: 450 | AF52: 350 | AG52: 400 | AH52: 385 | AI52: 390 | AJ52: 2909.09 | AK52: 2636.36 | AL52: 2416.67 | AM52: 2800 | AN52: 2500 | AO52: 2300 | AP52: 2200 | AQ52: 2300 | AR52: 2500
...

Sheet DASHBOARD
A2: KPI Overview | D2: Q4 2024
A3: Revenue Compared per year | I3: New Customers per year
A5: Revenue Actual VS Target | I5: New customers Actual VS Target
A7: =SUM(DATA!C16:E16) -> 2185000 | C7: Actual Revenue | I7: =SUM(DATA!R16:T16) -> 309 | K7: Actual New Customers
A9: =SUM(DATA!F16:H16) -> 2325000 | C9: Target Revenue | I9: =SUM(DATA!O16:Q16) -> 300 | K9: Target New Customers
A11: =A7/A9 -> 0.93978495 | C11: Target Achievement | I11: =I7/I9 -> 1.03 | K11: Target Achievement
A18: Average Revenue Per Year | I18: Customer Acquisition costs per year
A21: Avg. Revenue per Customer | I21: Customer Acquisition Cost
A23: =SUM(DATA!AJ16:AL16)/3 -> 1986.7647 | C23: Actual Revenue Per Customer | I23: =SUM(DATA!AA16:AC16)/3 -> 372.11067 | K23: Actual CAC
A25: =SUM(DATA!AP16:AR16)/3 -> 2500 | C25: Target Revnue Per Customer | I25: =SUM(DATA!AD16:AF16)/3 -> 333.33333 | K25: Target CAC
A27: =A23/A25 -> 0.79470587 | C27: Target Achievement | I27: =I23/I25 -> 1.116332 | K27: Target Achievement
